SearchBayesianSkopt: Config 0 Exception. Config: {'l1_ratio': 0.003183567349249954, 'alpha': 0.07166923356367623, 'positive_only': True, 'topK': 245} - Exception: Traceback (most recent call last):
  File "C:\Users\Luca\DataspellProjects\Recommender-Systems-Challenge-2022\HyperparameterTuning\SearchAbstractClass.py", line 468, in _objective_function
    result_df, recommender_instance = self._evaluate_on_validation(current_fit_hyperparameters_dict, was_already_evaluated_flag, was_already_evaluated_index)
  File "C:\Users\Luca\DataspellProjects\Recommender-Systems-Challenge-2022\HyperparameterTuning\SearchAbstractClass.py", line 326, in _evaluate_on_validation
    recommender_instance, train_time = self._fit_model(current_fit_hyperparameters)
  File "C:\Users\Luca\DataspellProjects\Recommender-Systems-Challenge-2022\HyperparameterTuning\SearchAbstractClass.py", line 297, in _fit_model
    recommender_instance.fit(*self.recommender_input_args.FIT_POSITIONAL_ARGS,
  File "C:\Users\Luca\miniconda3\lib\site-packages\sklearn\utils\_testing.py", line 320, in wrapper
    return fn(*args, **kwargs)
TypeError: fit() got an unexpected keyword argument 'validation_every_n'

SearchBayesianSkopt: Config 1 Exception. Config: {'l1_ratio': 0.00886093806520026, 'alpha': 0.023103099725073482, 'positive_only': True, 'topK': 420} - Exception: Traceback (most recent call last):
  File "C:\Users\Luca\DataspellProjects\Recommender-Systems-Challenge-2022\HyperparameterTuning\SearchAbstractClass.py", line 468, in _objective_function
    result_df, recommender_instance = self._evaluate_on_validation(current_fit_hyperparameters_dict, was_already_evaluated_flag, was_already_evaluated_index)
  File "C:\Users\Luca\DataspellProjects\Recommender-Systems-Challenge-2022\HyperparameterTuning\SearchAbstractClass.py", line 326, in _evaluate_on_validation
    recommender_instance, train_time = self._fit_model(current_fit_hyperparameters)
  File "C:\Users\Luca\DataspellProjects\Recommender-Systems-Challenge-2022\HyperparameterTuning\SearchAbstractClass.py", line 297, in _fit_model
    recommender_instance.fit(*self.recommender_input_args.FIT_POSITIONAL_ARGS,
  File "C:\Users\Luca\miniconda3\lib\site-packages\sklearn\utils\_testing.py", line 320, in wrapper
    return fn(*args, **kwargs)
TypeError: fit() got an unexpected keyword argument 'validation_every_n'

SearchBayesianSkopt: Config 2 Exception. Config: {'l1_ratio': 0.004219805979182752, 'alpha': 0.07251147143659786, 'positive_only': True, 'topK': 374} - Exception: Traceback (most recent call last):
  File "C:\Users\Luca\DataspellProjects\Recommender-Systems-Challenge-2022\HyperparameterTuning\SearchAbstractClass.py", line 468, in _objective_function
    result_df, recommender_instance = self._evaluate_on_validation(current_fit_hyperparameters_dict, was_already_evaluated_flag, was_already_evaluated_index)
  File "C:\Users\Luca\DataspellProjects\Recommender-Systems-Challenge-2022\HyperparameterTuning\SearchAbstractClass.py", line 326, in _evaluate_on_validation
    recommender_instance, train_time = self._fit_model(current_fit_hyperparameters)
  File "C:\Users\Luca\DataspellProjects\Recommender-Systems-Challenge-2022\HyperparameterTuning\SearchAbstractClass.py", line 297, in _fit_model
    recommender_instance.fit(*self.recommender_input_args.FIT_POSITIONAL_ARGS,
  File "C:\Users\Luca\miniconda3\lib\site-packages\sklearn\utils\_testing.py", line 320, in wrapper
    return fn(*args, **kwargs)
TypeError: fit() got an unexpected keyword argument 'validation_every_n'

SearchBayesianSkopt: Config 3 Exception. Config: {'l1_ratio': 0.003196171350897768, 'alpha': 0.03915950644390028, 'positive_only': True, 'topK': 237} - Exception: Traceback (most recent call last):
  File "C:\Users\Luca\DataspellProjects\Recommender-Systems-Challenge-2022\HyperparameterTuning\SearchAbstractClass.py", line 468, in _objective_function
    result_df, recommender_instance = self._evaluate_on_validation(current_fit_hyperparameters_dict, was_already_evaluated_flag, was_already_evaluated_index)
  File "C:\Users\Luca\DataspellProjects\Recommender-Systems-Challenge-2022\HyperparameterTuning\SearchAbstractClass.py", line 326, in _evaluate_on_validation
    recommender_instance, train_time = self._fit_model(current_fit_hyperparameters)
  File "C:\Users\Luca\DataspellProjects\Recommender-Systems-Challenge-2022\HyperparameterTuning\SearchAbstractClass.py", line 297, in _fit_model
    recommender_instance.fit(*self.recommender_input_args.FIT_POSITIONAL_ARGS,
  File "C:\Users\Luca\miniconda3\lib\site-packages\sklearn\utils\_testing.py", line 320, in wrapper
    return fn(*args, **kwargs)
TypeError: fit() got an unexpected keyword argument 'validation_every_n'

SearchBayesianSkopt: Config 4 Exception. Config: {'l1_ratio': 0.001330864591820635, 'alpha': 0.017939683124930494, 'positive_only': True, 'topK': 329} - Exception: Traceback (most recent call last):
  File "C:\Users\Luca\DataspellProjects\Recommender-Systems-Challenge-2022\HyperparameterTuning\SearchAbstractClass.py", line 468, in _objective_function
    result_df, recommender_instance = self._evaluate_on_validation(current_fit_hyperparameters_dict, was_already_evaluated_flag, was_already_evaluated_index)
  File "C:\Users\Luca\DataspellProjects\Recommender-Systems-Challenge-2022\HyperparameterTuning\SearchAbstractClass.py", line 326, in _evaluate_on_validation
    recommender_instance, train_time = self._fit_model(current_fit_hyperparameters)
  File "C:\Users\Luca\DataspellProjects\Recommender-Systems-Challenge-2022\HyperparameterTuning\SearchAbstractClass.py", line 297, in _fit_model
    recommender_instance.fit(*self.recommender_input_args.FIT_POSITIONAL_ARGS,
  File "C:\Users\Luca\miniconda3\lib\site-packages\sklearn\utils\_testing.py", line 320, in wrapper
    return fn(*args, **kwargs)
TypeError: fit() got an unexpected keyword argument 'validation_every_n'

SearchBayesianSkopt: Config 5 Exception. Config: {'l1_ratio': 0.0014338377451667652, 'alpha': 0.021192402523163654, 'positive_only': True, 'topK': 446} - Exception: Traceback (most recent call last):
  File "C:\Users\Luca\DataspellProjects\Recommender-Systems-Challenge-2022\HyperparameterTuning\SearchAbstractClass.py", line 468, in _objective_function
    result_df, recommender_instance = self._evaluate_on_validation(current_fit_hyperparameters_dict, was_already_evaluated_flag, was_already_evaluated_index)
  File "C:\Users\Luca\DataspellProjects\Recommender-Systems-Challenge-2022\HyperparameterTuning\SearchAbstractClass.py", line 326, in _evaluate_on_validation
    recommender_instance, train_time = self._fit_model(current_fit_hyperparameters)
  File "C:\Users\Luca\DataspellProjects\Recommender-Systems-Challenge-2022\HyperparameterTuning\SearchAbstractClass.py", line 297, in _fit_model
    recommender_instance.fit(*self.recommender_input_args.FIT_POSITIONAL_ARGS,
  File "C:\Users\Luca\miniconda3\lib\site-packages\sklearn\utils\_testing.py", line 320, in wrapper
    return fn(*args, **kwargs)
TypeError: fit() got an unexpected keyword argument 'validation_every_n'

SearchBayesianSkopt: Config 6 Exception. Config: {'l1_ratio': 0.0013546785316843756, 'alpha': 0.03892472293507244, 'positive_only': True, 'topK': 397} - Exception: Traceback (most recent call last):
  File "C:\Users\Luca\DataspellProjects\Recommender-Systems-Challenge-2022\HyperparameterTuning\SearchAbstractClass.py", line 468, in _objective_function
    result_df, recommender_instance = self._evaluate_on_validation(current_fit_hyperparameters_dict, was_already_evaluated_flag, was_already_evaluated_index)
  File "C:\Users\Luca\DataspellProjects\Recommender-Systems-Challenge-2022\HyperparameterTuning\SearchAbstractClass.py", line 326, in _evaluate_on_validation
    recommender_instance, train_time = self._fit_model(current_fit_hyperparameters)
  File "C:\Users\Luca\DataspellProjects\Recommender-Systems-Challenge-2022\HyperparameterTuning\SearchAbstractClass.py", line 297, in _fit_model
    recommender_instance.fit(*self.recommender_input_args.FIT_POSITIONAL_ARGS,
  File "C:\Users\Luca\miniconda3\lib\site-packages\sklearn\utils\_testing.py", line 320, in wrapper
    return fn(*args, **kwargs)
TypeError: fit() got an unexpected keyword argument 'validation_every_n'

SearchBayesianSkopt: Config 7 Exception. Config: {'l1_ratio': 0.003064099749027975, 'alpha': 0.02652663943872226, 'positive_only': True, 'topK': 367} - Exception: Traceback (most recent call last):
  File "C:\Users\Luca\DataspellProjects\Recommender-Systems-Challenge-2022\HyperparameterTuning\SearchAbstractClass.py", line 468, in _objective_function
    result_df, recommender_instance = self._evaluate_on_validation(current_fit_hyperparameters_dict, was_already_evaluated_flag, was_already_evaluated_index)
  File "C:\Users\Luca\DataspellProjects\Recommender-Systems-Challenge-2022\HyperparameterTuning\SearchAbstractClass.py", line 326, in _evaluate_on_validation
    recommender_instance, train_time = self._fit_model(current_fit_hyperparameters)
  File "C:\Users\Luca\DataspellProjects\Recommender-Systems-Challenge-2022\HyperparameterTuning\SearchAbstractClass.py", line 297, in _fit_model
    recommender_instance.fit(*self.recommender_input_args.FIT_POSITIONAL_ARGS,
  File "C:\Users\Luca\miniconda3\lib\site-packages\sklearn\utils\_testing.py", line 320, in wrapper
    return fn(*args, **kwargs)
TypeError: fit() got an unexpected keyword argument 'validation_every_n'

SearchBayesianSkopt: Config 8 Exception. Config: {'l1_ratio': 0.0028453001593016663, 'alpha': 0.02034966857487157, 'positive_only': True, 'topK': 366} - Exception: Traceback (most recent call last):
  File "C:\Users\Luca\DataspellProjects\Recommender-Systems-Challenge-2022\HyperparameterTuning\SearchAbstractClass.py", line 468, in _objective_function
    result_df, recommender_instance = self._evaluate_on_validation(current_fit_hyperparameters_dict, was_already_evaluated_flag, was_already_evaluated_index)
  File "C:\Users\Luca\DataspellProjects\Recommender-Systems-Challenge-2022\HyperparameterTuning\SearchAbstractClass.py", line 326, in _evaluate_on_validation
    recommender_instance, train_time = self._fit_model(current_fit_hyperparameters)
  File "C:\Users\Luca\DataspellProjects\Recommender-Systems-Challenge-2022\HyperparameterTuning\SearchAbstractClass.py", line 297, in _fit_model
    recommender_instance.fit(*self.recommender_input_args.FIT_POSITIONAL_ARGS,
  File "C:\Users\Luca\miniconda3\lib\site-packages\sklearn\utils\_testing.py", line 320, in wrapper
    return fn(*args, **kwargs)
TypeError: fit() got an unexpected keyword argument 'validation_every_n'

SearchBayesianSkopt: Config 9 Exception. Config: {'l1_ratio': 0.0028910130925582636, 'alpha': 0.013004002541920698, 'positive_only': True, 'topK': 339} - Exception: Traceback (most recent call last):
  File "C:\Users\Luca\DataspellProjects\Recommender-Systems-Challenge-2022\HyperparameterTuning\SearchAbstractClass.py", line 468, in _objective_function
    result_df, recommender_instance = self._evaluate_on_validation(current_fit_hyperparameters_dict, was_already_evaluated_flag, was_already_evaluated_index)
  File "C:\Users\Luca\DataspellProjects\Recommender-Systems-Challenge-2022\HyperparameterTuning\SearchAbstractClass.py", line 326, in _evaluate_on_validation
    recommender_instance, train_time = self._fit_model(current_fit_hyperparameters)
  File "C:\Users\Luca\DataspellProjects\Recommender-Systems-Challenge-2022\HyperparameterTuning\SearchAbstractClass.py", line 297, in _fit_model
    recommender_instance.fit(*self.recommender_input_args.FIT_POSITIONAL_ARGS,
  File "C:\Users\Luca\miniconda3\lib\site-packages\sklearn\utils\_testing.py", line 320, in wrapper
    return fn(*args, **kwargs)
TypeError: fit() got an unexpected keyword argument 'validation_every_n'

SearchBayesianSkopt: Config 10 Exception. Config: {'l1_ratio': 0.002167610133666832, 'alpha': 0.017413323447568258, 'positive_only': True, 'topK': 421} - Exception: Traceback (most recent call last):
  File "C:\Users\Luca\DataspellProjects\Recommender-Systems-Challenge-2022\HyperparameterTuning\SearchAbstractClass.py", line 468, in _objective_function
    result_df, recommender_instance = self._evaluate_on_validation(current_fit_hyperparameters_dict, was_already_evaluated_flag, was_already_evaluated_index)
  File "C:\Users\Luca\DataspellProjects\Recommender-Systems-Challenge-2022\HyperparameterTuning\SearchAbstractClass.py", line 326, in _evaluate_on_validation
    recommender_instance, train_time = self._fit_model(current_fit_hyperparameters)
  File "C:\Users\Luca\DataspellProjects\Recommender-Systems-Challenge-2022\HyperparameterTuning\SearchAbstractClass.py", line 297, in _fit_model
    recommender_instance.fit(*self.recommender_input_args.FIT_POSITIONAL_ARGS,
  File "C:\Users\Luca\miniconda3\lib\site-packages\sklearn\utils\_testing.py", line 320, in wrapper
    return fn(*args, **kwargs)
TypeError: fit() got an unexpected keyword argument 'validation_every_n'

SearchBayesianSkopt: Config 11 Exception. Config: {'l1_ratio': 0.0022598055108969638, 'alpha': 0.032409814536710456, 'positive_only': True, 'topK': 290} - Exception: Traceback (most recent call last):
  File "C:\Users\Luca\DataspellProjects\Recommender-Systems-Challenge-2022\HyperparameterTuning\SearchAbstractClass.py", line 468, in _objective_function
    result_df, recommender_instance = self._evaluate_on_validation(current_fit_hyperparameters_dict, was_already_evaluated_flag, was_already_evaluated_index)
  File "C:\Users\Luca\DataspellProjects\Recommender-Systems-Challenge-2022\HyperparameterTuning\SearchAbstractClass.py", line 326, in _evaluate_on_validation
    recommender_instance, train_time = self._fit_model(current_fit_hyperparameters)
  File "C:\Users\Luca\DataspellProjects\Recommender-Systems-Challenge-2022\HyperparameterTuning\SearchAbstractClass.py", line 297, in _fit_model
    recommender_instance.fit(*self.recommender_input_args.FIT_POSITIONAL_ARGS,
  File "C:\Users\Luca\miniconda3\lib\site-packages\sklearn\utils\_testing.py", line 320, in wrapper
    return fn(*args, **kwargs)
TypeError: fit() got an unexpected keyword argument 'validation_every_n'

SearchBayesianSkopt: Config 12 Exception. Config: {'l1_ratio': 0.0015841611416699726, 'alpha': 0.027897741754022386, 'positive_only': True, 'topK': 346} - Exception: Traceback (most recent call last):
  File "C:\Users\Luca\DataspellProjects\Recommender-Systems-Challenge-2022\HyperparameterTuning\SearchAbstractClass.py", line 468, in _objective_function
    result_df, recommender_instance = self._evaluate_on_validation(current_fit_hyperparameters_dict, was_already_evaluated_flag, was_already_evaluated_index)
  File "C:\Users\Luca\DataspellProjects\Recommender-Systems-Challenge-2022\HyperparameterTuning\SearchAbstractClass.py", line 326, in _evaluate_on_validation
    recommender_instance, train_time = self._fit_model(current_fit_hyperparameters)
  File "C:\Users\Luca\DataspellProjects\Recommender-Systems-Challenge-2022\HyperparameterTuning\SearchAbstractClass.py", line 297, in _fit_model
    recommender_instance.fit(*self.recommender_input_args.FIT_POSITIONAL_ARGS,
  File "C:\Users\Luca\miniconda3\lib\site-packages\sklearn\utils\_testing.py", line 320, in wrapper
    return fn(*args, **kwargs)
TypeError: fit() got an unexpected keyword argument 'validation_every_n'

SearchBayesianSkopt: Config 13 Exception. Config: {'l1_ratio': 0.0015202986495068402, 'alpha': 0.02659997255409595, 'positive_only': True, 'topK': 257} - Exception: Traceback (most recent call last):
  File "C:\Users\Luca\DataspellProjects\Recommender-Systems-Challenge-2022\HyperparameterTuning\SearchAbstractClass.py", line 468, in _objective_function
    result_df, recommender_instance = self._evaluate_on_validation(current_fit_hyperparameters_dict, was_already_evaluated_flag, was_already_evaluated_index)
  File "C:\Users\Luca\DataspellProjects\Recommender-Systems-Challenge-2022\HyperparameterTuning\SearchAbstractClass.py", line 326, in _evaluate_on_validation
    recommender_instance, train_time = self._fit_model(current_fit_hyperparameters)
  File "C:\Users\Luca\DataspellProjects\Recommender-Systems-Challenge-2022\HyperparameterTuning\SearchAbstractClass.py", line 297, in _fit_model
    recommender_instance.fit(*self.recommender_input_args.FIT_POSITIONAL_ARGS,
  File "C:\Users\Luca\miniconda3\lib\site-packages\sklearn\utils\_testing.py", line 320, in wrapper
    return fn(*args, **kwargs)
TypeError: fit() got an unexpected keyword argument 'validation_every_n'

SearchBayesianSkopt: Config 14 Exception. Config: {'l1_ratio': 0.005710405138784147, 'alpha': 0.02790729085330083, 'positive_only': True, 'topK': 259} - Exception: Traceback (most recent call last):
  File "C:\Users\Luca\DataspellProjects\Recommender-Systems-Challenge-2022\HyperparameterTuning\SearchAbstractClass.py", line 468, in _objective_function
    result_df, recommender_instance = self._evaluate_on_validation(current_fit_hyperparameters_dict, was_already_evaluated_flag, was_already_evaluated_index)
  File "C:\Users\Luca\DataspellProjects\Recommender-Systems-Challenge-2022\HyperparameterTuning\SearchAbstractClass.py", line 326, in _evaluate_on_validation
    recommender_instance, train_time = self._fit_model(current_fit_hyperparameters)
  File "C:\Users\Luca\DataspellProjects\Recommender-Systems-Challenge-2022\HyperparameterTuning\SearchAbstractClass.py", line 297, in _fit_model
    recommender_instance.fit(*self.recommender_input_args.FIT_POSITIONAL_ARGS,
  File "C:\Users\Luca\miniconda3\lib\site-packages\sklearn\utils\_testing.py", line 320, in wrapper
    return fn(*args, **kwargs)
TypeError: fit() got an unexpected keyword argument 'validation_every_n'

SearchBayesianSkopt: Search interrupted. No valid config was found during the initial random initialization
SearchBayesianSkopt: Config 0 Exception. Config: {'topK': 320, 'l1_ratio': 0.007240528898040849, 'alpha': 0.020933593809778914} - Exception: Traceback (most recent call last):
  File "C:\Users\Luca\DataspellProjects\Recommender-Systems-Challenge-2022\HyperparameterTuning\SearchAbstractClass.py", line 468, in _objective_function
    result_df, recommender_instance = self._evaluate_on_validation(current_fit_hyperparameters_dict, was_already_evaluated_flag, was_already_evaluated_index)
  File "C:\Users\Luca\DataspellProjects\Recommender-Systems-Challenge-2022\HyperparameterTuning\SearchAbstractClass.py", line 326, in _evaluate_on_validation
    recommender_instance, train_time = self._fit_model(current_fit_hyperparameters)
  File "C:\Users\Luca\DataspellProjects\Recommender-Systems-Challenge-2022\HyperparameterTuning\SearchAbstractClass.py", line 297, in _fit_model
    recommender_instance.fit(*self.recommender_input_args.FIT_POSITIONAL_ARGS,
  File "C:\Users\Luca\miniconda3\lib\site-packages\sklearn\utils\_testing.py", line 320, in wrapper
    return fn(*args, **kwargs)
TypeError: fit() got an unexpected keyword argument 'validation_every_n'

SearchBayesianSkopt: Config 1 Exception. Config: {'topK': 424, 'l1_ratio': 0.003211731062576318, 'alpha': 0.0791259074884496} - Exception: Traceback (most recent call last):
  File "C:\Users\Luca\DataspellProjects\Recommender-Systems-Challenge-2022\HyperparameterTuning\SearchAbstractClass.py", line 468, in _objective_function
    result_df, recommender_instance = self._evaluate_on_validation(current_fit_hyperparameters_dict, was_already_evaluated_flag, was_already_evaluated_index)
  File "C:\Users\Luca\DataspellProjects\Recommender-Systems-Challenge-2022\HyperparameterTuning\SearchAbstractClass.py", line 326, in _evaluate_on_validation
    recommender_instance, train_time = self._fit_model(current_fit_hyperparameters)
  File "C:\Users\Luca\DataspellProjects\Recommender-Systems-Challenge-2022\HyperparameterTuning\SearchAbstractClass.py", line 297, in _fit_model
    recommender_instance.fit(*self.recommender_input_args.FIT_POSITIONAL_ARGS,
  File "C:\Users\Luca\miniconda3\lib\site-packages\sklearn\utils\_testing.py", line 320, in wrapper
    return fn(*args, **kwargs)
TypeError: fit() got an unexpected keyword argument 'validation_every_n'

SearchBayesianSkopt: Config 2 Exception. Config: {'topK': 204, 'l1_ratio': 0.001410144922848643, 'alpha': 0.06598303556688212} - Exception: Traceback (most recent call last):
  File "C:\Users\Luca\DataspellProjects\Recommender-Systems-Challenge-2022\HyperparameterTuning\SearchAbstractClass.py", line 468, in _objective_function
    result_df, recommender_instance = self._evaluate_on_validation(current_fit_hyperparameters_dict, was_already_evaluated_flag, was_already_evaluated_index)
  File "C:\Users\Luca\DataspellProjects\Recommender-Systems-Challenge-2022\HyperparameterTuning\SearchAbstractClass.py", line 326, in _evaluate_on_validation
    recommender_instance, train_time = self._fit_model(current_fit_hyperparameters)
  File "C:\Users\Luca\DataspellProjects\Recommender-Systems-Challenge-2022\HyperparameterTuning\SearchAbstractClass.py", line 297, in _fit_model
    recommender_instance.fit(*self.recommender_input_args.FIT_POSITIONAL_ARGS,
  File "C:\Users\Luca\miniconda3\lib\site-packages\sklearn\utils\_testing.py", line 320, in wrapper
    return fn(*args, **kwargs)
TypeError: fit() got an unexpected keyword argument 'validation_every_n'

SearchBayesianSkopt: Config 3 Exception. Config: {'topK': 256, 'l1_ratio': 0.0013177327579711438, 'alpha': 0.01242008968090208} - Exception: Traceback (most recent call last):
  File "C:\Users\Luca\DataspellProjects\Recommender-Systems-Challenge-2022\HyperparameterTuning\SearchAbstractClass.py", line 468, in _objective_function
    result_df, recommender_instance = self._evaluate_on_validation(current_fit_hyperparameters_dict, was_already_evaluated_flag, was_already_evaluated_index)
  File "C:\Users\Luca\DataspellProjects\Recommender-Systems-Challenge-2022\HyperparameterTuning\SearchAbstractClass.py", line 326, in _evaluate_on_validation
    recommender_instance, train_time = self._fit_model(current_fit_hyperparameters)
  File "C:\Users\Luca\DataspellProjects\Recommender-Systems-Challenge-2022\HyperparameterTuning\SearchAbstractClass.py", line 297, in _fit_model
    recommender_instance.fit(*self.recommender_input_args.FIT_POSITIONAL_ARGS,
  File "C:\Users\Luca\miniconda3\lib\site-packages\sklearn\utils\_testing.py", line 320, in wrapper
    return fn(*args, **kwargs)
TypeError: fit() got an unexpected keyword argument 'validation_every_n'

SearchBayesianSkopt: Config 4 Exception. Config: {'topK': 228, 'l1_ratio': 0.00450995125661152, 'alpha': 0.09564952479586618} - Exception: Traceback (most recent call last):
  File "C:\Users\Luca\DataspellProjects\Recommender-Systems-Challenge-2022\HyperparameterTuning\SearchAbstractClass.py", line 468, in _objective_function
    result_df, recommender_instance = self._evaluate_on_validation(current_fit_hyperparameters_dict, was_already_evaluated_flag, was_already_evaluated_index)
  File "C:\Users\Luca\DataspellProjects\Recommender-Systems-Challenge-2022\HyperparameterTuning\SearchAbstractClass.py", line 326, in _evaluate_on_validation
    recommender_instance, train_time = self._fit_model(current_fit_hyperparameters)
  File "C:\Users\Luca\DataspellProjects\Recommender-Systems-Challenge-2022\HyperparameterTuning\SearchAbstractClass.py", line 297, in _fit_model
    recommender_instance.fit(*self.recommender_input_args.FIT_POSITIONAL_ARGS,
  File "C:\Users\Luca\miniconda3\lib\site-packages\sklearn\utils\_testing.py", line 320, in wrapper
    return fn(*args, **kwargs)
TypeError: fit() got an unexpected keyword argument 'validation_every_n'

SearchBayesianSkopt: Config 5 Exception. Config: {'topK': 339, 'l1_ratio': 0.0020302957092468406, 'alpha': 0.032662748769717885} - Exception: Traceback (most recent call last):
  File "C:\Users\Luca\DataspellProjects\Recommender-Systems-Challenge-2022\HyperparameterTuning\SearchAbstractClass.py", line 468, in _objective_function
    result_df, recommender_instance = self._evaluate_on_validation(current_fit_hyperparameters_dict, was_already_evaluated_flag, was_already_evaluated_index)
  File "C:\Users\Luca\DataspellProjects\Recommender-Systems-Challenge-2022\HyperparameterTuning\SearchAbstractClass.py", line 326, in _evaluate_on_validation
    recommender_instance, train_time = self._fit_model(current_fit_hyperparameters)
  File "C:\Users\Luca\DataspellProjects\Recommender-Systems-Challenge-2022\HyperparameterTuning\SearchAbstractClass.py", line 297, in _fit_model
    recommender_instance.fit(*self.recommender_input_args.FIT_POSITIONAL_ARGS,
  File "C:\Users\Luca\miniconda3\lib\site-packages\sklearn\utils\_testing.py", line 320, in wrapper
    return fn(*args, **kwargs)
TypeError: fit() got an unexpected keyword argument 'validation_every_n'

SearchBayesianSkopt: Config 6 Exception. Config: {'topK': 284, 'l1_ratio': 0.0012603392096057296, 'alpha': 0.05402756272348536} - Exception: Traceback (most recent call last):
  File "C:\Users\Luca\DataspellProjects\Recommender-Systems-Challenge-2022\HyperparameterTuning\SearchAbstractClass.py", line 468, in _objective_function
    result_df, recommender_instance = self._evaluate_on_validation(current_fit_hyperparameters_dict, was_already_evaluated_flag, was_already_evaluated_index)
  File "C:\Users\Luca\DataspellProjects\Recommender-Systems-Challenge-2022\HyperparameterTuning\SearchAbstractClass.py", line 326, in _evaluate_on_validation
    recommender_instance, train_time = self._fit_model(current_fit_hyperparameters)
  File "C:\Users\Luca\DataspellProjects\Recommender-Systems-Challenge-2022\HyperparameterTuning\SearchAbstractClass.py", line 297, in _fit_model
    recommender_instance.fit(*self.recommender_input_args.FIT_POSITIONAL_ARGS,
  File "C:\Users\Luca\miniconda3\lib\site-packages\sklearn\utils\_testing.py", line 320, in wrapper
    return fn(*args, **kwargs)
TypeError: fit() got an unexpected keyword argument 'validation_every_n'

SearchBayesianSkopt: Config 7 Exception. Config: {'topK': 225, 'l1_ratio': 0.0033694657692128604, 'alpha': 0.04574097078773788} - Exception: Traceback (most recent call last):
  File "C:\Users\Luca\DataspellProjects\Recommender-Systems-Challenge-2022\HyperparameterTuning\SearchAbstractClass.py", line 468, in _objective_function
    result_df, recommender_instance = self._evaluate_on_validation(current_fit_hyperparameters_dict, was_already_evaluated_flag, was_already_evaluated_index)
  File "C:\Users\Luca\DataspellProjects\Recommender-Systems-Challenge-2022\HyperparameterTuning\SearchAbstractClass.py", line 326, in _evaluate_on_validation
    recommender_instance, train_time = self._fit_model(current_fit_hyperparameters)
  File "C:\Users\Luca\DataspellProjects\Recommender-Systems-Challenge-2022\HyperparameterTuning\SearchAbstractClass.py", line 297, in _fit_model
    recommender_instance.fit(*self.recommender_input_args.FIT_POSITIONAL_ARGS,
  File "C:\Users\Luca\miniconda3\lib\site-packages\sklearn\utils\_testing.py", line 320, in wrapper
    return fn(*args, **kwargs)
TypeError: fit() got an unexpected keyword argument 'validation_every_n'

SearchBayesianSkopt: Config 8 Exception. Config: {'topK': 378, 'l1_ratio': 0.0015970888659694647, 'alpha': 0.01590070749466958} - Exception: Traceback (most recent call last):
  File "C:\Users\Luca\DataspellProjects\Recommender-Systems-Challenge-2022\HyperparameterTuning\SearchAbstractClass.py", line 468, in _objective_function
    result_df, recommender_instance = self._evaluate_on_validation(current_fit_hyperparameters_dict, was_already_evaluated_flag, was_already_evaluated_index)
  File "C:\Users\Luca\DataspellProjects\Recommender-Systems-Challenge-2022\HyperparameterTuning\SearchAbstractClass.py", line 326, in _evaluate_on_validation
    recommender_instance, train_time = self._fit_model(current_fit_hyperparameters)
  File "C:\Users\Luca\DataspellProjects\Recommender-Systems-Challenge-2022\HyperparameterTuning\SearchAbstractClass.py", line 297, in _fit_model
    recommender_instance.fit(*self.recommender_input_args.FIT_POSITIONAL_ARGS,
  File "C:\Users\Luca\miniconda3\lib\site-packages\sklearn\utils\_testing.py", line 320, in wrapper
    return fn(*args, **kwargs)
TypeError: fit() got an unexpected keyword argument 'validation_every_n'

SearchBayesianSkopt: Config 9 Exception. Config: {'topK': 229, 'l1_ratio': 0.007673094433598624, 'alpha': 0.0491402065109908} - Exception: Traceback (most recent call last):
  File "C:\Users\Luca\DataspellProjects\Recommender-Systems-Challenge-2022\HyperparameterTuning\SearchAbstractClass.py", line 468, in _objective_function
    result_df, recommender_instance = self._evaluate_on_validation(current_fit_hyperparameters_dict, was_already_evaluated_flag, was_already_evaluated_index)
  File "C:\Users\Luca\DataspellProjects\Recommender-Systems-Challenge-2022\HyperparameterTuning\SearchAbstractClass.py", line 326, in _evaluate_on_validation
    recommender_instance, train_time = self._fit_model(current_fit_hyperparameters)
  File "C:\Users\Luca\DataspellProjects\Recommender-Systems-Challenge-2022\HyperparameterTuning\SearchAbstractClass.py", line 297, in _fit_model
    recommender_instance.fit(*self.recommender_input_args.FIT_POSITIONAL_ARGS,
  File "C:\Users\Luca\miniconda3\lib\site-packages\sklearn\utils\_testing.py", line 320, in wrapper
    return fn(*args, **kwargs)
TypeError: fit() got an unexpected keyword argument 'validation_every_n'

SearchBayesianSkopt: Config 10 Exception. Config: {'topK': 277, 'l1_ratio': 0.004923729556851326, 'alpha': 0.010194304445059716} - Exception: Traceback (most recent call last):
  File "C:\Users\Luca\DataspellProjects\Recommender-Systems-Challenge-2022\HyperparameterTuning\SearchAbstractClass.py", line 468, in _objective_function
    result_df, recommender_instance = self._evaluate_on_validation(current_fit_hyperparameters_dict, was_already_evaluated_flag, was_already_evaluated_index)
  File "C:\Users\Luca\DataspellProjects\Recommender-Systems-Challenge-2022\HyperparameterTuning\SearchAbstractClass.py", line 326, in _evaluate_on_validation
    recommender_instance, train_time = self._fit_model(current_fit_hyperparameters)
  File "C:\Users\Luca\DataspellProjects\Recommender-Systems-Challenge-2022\HyperparameterTuning\SearchAbstractClass.py", line 297, in _fit_model
    recommender_instance.fit(*self.recommender_input_args.FIT_POSITIONAL_ARGS,
  File "C:\Users\Luca\miniconda3\lib\site-packages\sklearn\utils\_testing.py", line 320, in wrapper
    return fn(*args, **kwargs)
TypeError: fit() got an unexpected keyword argument 'validation_every_n'

SearchBayesianSkopt: Config 11 Exception. Config: {'topK': 323, 'l1_ratio': 0.007091912739258281, 'alpha': 0.013410274396480272} - Exception: Traceback (most recent call last):
  File "C:\Users\Luca\DataspellProjects\Recommender-Systems-Challenge-2022\HyperparameterTuning\SearchAbstractClass.py", line 468, in _objective_function
    result_df, recommender_instance = self._evaluate_on_validation(current_fit_hyperparameters_dict, was_already_evaluated_flag, was_already_evaluated_index)
  File "C:\Users\Luca\DataspellProjects\Recommender-Systems-Challenge-2022\HyperparameterTuning\SearchAbstractClass.py", line 326, in _evaluate_on_validation
    recommender_instance, train_time = self._fit_model(current_fit_hyperparameters)
  File "C:\Users\Luca\DataspellProjects\Recommender-Systems-Challenge-2022\HyperparameterTuning\SearchAbstractClass.py", line 297, in _fit_model
    recommender_instance.fit(*self.recommender_input_args.FIT_POSITIONAL_ARGS,
  File "C:\Users\Luca\miniconda3\lib\site-packages\sklearn\utils\_testing.py", line 320, in wrapper
    return fn(*args, **kwargs)
TypeError: fit() got an unexpected keyword argument 'validation_every_n'

SearchBayesianSkopt: Config 12 Exception. Config: {'topK': 332, 'l1_ratio': 0.0069408339378282296, 'alpha': 0.016124556728382033} - Exception: Traceback (most recent call last):
  File "C:\Users\Luca\DataspellProjects\Recommender-Systems-Challenge-2022\HyperparameterTuning\SearchAbstractClass.py", line 468, in _objective_function
    result_df, recommender_instance = self._evaluate_on_validation(current_fit_hyperparameters_dict, was_already_evaluated_flag, was_already_evaluated_index)
  File "C:\Users\Luca\DataspellProjects\Recommender-Systems-Challenge-2022\HyperparameterTuning\SearchAbstractClass.py", line 326, in _evaluate_on_validation
    recommender_instance, train_time = self._fit_model(current_fit_hyperparameters)
  File "C:\Users\Luca\DataspellProjects\Recommender-Systems-Challenge-2022\HyperparameterTuning\SearchAbstractClass.py", line 297, in _fit_model
    recommender_instance.fit(*self.recommender_input_args.FIT_POSITIONAL_ARGS,
  File "C:\Users\Luca\miniconda3\lib\site-packages\sklearn\utils\_testing.py", line 320, in wrapper
    return fn(*args, **kwargs)
TypeError: fit() got an unexpected keyword argument 'validation_every_n'

SearchBayesianSkopt: Config 13 Exception. Config: {'topK': 335, 'l1_ratio': 0.0034719291877940346, 'alpha': 0.030341688457632788} - Exception: Traceback (most recent call last):
  File "C:\Users\Luca\DataspellProjects\Recommender-Systems-Challenge-2022\HyperparameterTuning\SearchAbstractClass.py", line 468, in _objective_function
    result_df, recommender_instance = self._evaluate_on_validation(current_fit_hyperparameters_dict, was_already_evaluated_flag, was_already_evaluated_index)
  File "C:\Users\Luca\DataspellProjects\Recommender-Systems-Challenge-2022\HyperparameterTuning\SearchAbstractClass.py", line 326, in _evaluate_on_validation
    recommender_instance, train_time = self._fit_model(current_fit_hyperparameters)
  File "C:\Users\Luca\DataspellProjects\Recommender-Systems-Challenge-2022\HyperparameterTuning\SearchAbstractClass.py", line 297, in _fit_model
    recommender_instance.fit(*self.recommender_input_args.FIT_POSITIONAL_ARGS,
  File "C:\Users\Luca\miniconda3\lib\site-packages\sklearn\utils\_testing.py", line 320, in wrapper
    return fn(*args, **kwargs)
TypeError: fit() got an unexpected keyword argument 'validation_every_n'

SearchBayesianSkopt: Config 14 Exception. Config: {'topK': 272, 'l1_ratio': 0.002983403378071439, 'alpha': 0.09691905358360806} - Exception: Traceback (most recent call last):
  File "C:\Users\Luca\DataspellProjects\Recommender-Systems-Challenge-2022\HyperparameterTuning\SearchAbstractClass.py", line 468, in _objective_function
    result_df, recommender_instance = self._evaluate_on_validation(current_fit_hyperparameters_dict, was_already_evaluated_flag, was_already_evaluated_index)
  File "C:\Users\Luca\DataspellProjects\Recommender-Systems-Challenge-2022\HyperparameterTuning\SearchAbstractClass.py", line 326, in _evaluate_on_validation
    recommender_instance, train_time = self._fit_model(current_fit_hyperparameters)
  File "C:\Users\Luca\DataspellProjects\Recommender-Systems-Challenge-2022\HyperparameterTuning\SearchAbstractClass.py", line 297, in _fit_model
    recommender_instance.fit(*self.recommender_input_args.FIT_POSITIONAL_ARGS,
  File "C:\Users\Luca\miniconda3\lib\site-packages\sklearn\utils\_testing.py", line 320, in wrapper
    return fn(*args, **kwargs)
TypeError: fit() got an unexpected keyword argument 'validation_every_n'

SearchBayesianSkopt: Search interrupted. No valid config was found during the initial random initialization
SearchBayesianSkopt: Config 0 Exception. Config: {'topK': 212, 'l1_ratio': 0.004741595001750328, 'alpha': 0.037423400488460025} - Exception: Traceback (most recent call last):
  File "C:\Users\Luca\DataspellProjects\Recommender-Systems-Challenge-2022\HyperparameterTuning\SearchAbstractClass.py", line 468, in _objective_function
    result_df, recommender_instance = self._evaluate_on_validation(current_fit_hyperparameters_dict, was_already_evaluated_flag, was_already_evaluated_index)
  File "C:\Users\Luca\DataspellProjects\Recommender-Systems-Challenge-2022\HyperparameterTuning\SearchAbstractClass.py", line 326, in _evaluate_on_validation
    recommender_instance, train_time = self._fit_model(current_fit_hyperparameters)
  File "C:\Users\Luca\DataspellProjects\Recommender-Systems-Challenge-2022\HyperparameterTuning\SearchAbstractClass.py", line 297, in _fit_model
    recommender_instance.fit(*self.recommender_input_args.FIT_POSITIONAL_ARGS,
  File "C:\Users\Luca\miniconda3\lib\site-packages\sklearn\utils\_testing.py", line 320, in wrapper
    return fn(*args, **kwargs)
TypeError: fit() got an unexpected keyword argument 'validation_every_n'

SearchBayesianSkopt: Config 1 Exception. Config: {'topK': 416, 'l1_ratio': 0.0011125838343857138, 'alpha': 0.020759033588656977} - Exception: Traceback (most recent call last):
  File "C:\Users\Luca\DataspellProjects\Recommender-Systems-Challenge-2022\HyperparameterTuning\SearchAbstractClass.py", line 468, in _objective_function
    result_df, recommender_instance = self._evaluate_on_validation(current_fit_hyperparameters_dict, was_already_evaluated_flag, was_already_evaluated_index)
  File "C:\Users\Luca\DataspellProjects\Recommender-Systems-Challenge-2022\HyperparameterTuning\SearchAbstractClass.py", line 326, in _evaluate_on_validation
    recommender_instance, train_time = self._fit_model(current_fit_hyperparameters)
  File "C:\Users\Luca\DataspellProjects\Recommender-Systems-Challenge-2022\HyperparameterTuning\SearchAbstractClass.py", line 297, in _fit_model
    recommender_instance.fit(*self.recommender_input_args.FIT_POSITIONAL_ARGS,
  File "C:\Users\Luca\miniconda3\lib\site-packages\sklearn\utils\_testing.py", line 320, in wrapper
    return fn(*args, **kwargs)
TypeError: fit() got an unexpected keyword argument 'validation_every_n'

SearchBayesianSkopt: Config 2 Exception. Config: {'topK': 299, 'l1_ratio': 0.007710550178390534, 'alpha': 0.03899393810754984} - Exception: Traceback (most recent call last):
  File "C:\Users\Luca\DataspellProjects\Recommender-Systems-Challenge-2022\HyperparameterTuning\SearchAbstractClass.py", line 468, in _objective_function
    result_df, recommender_instance = self._evaluate_on_validation(current_fit_hyperparameters_dict, was_already_evaluated_flag, was_already_evaluated_index)
  File "C:\Users\Luca\DataspellProjects\Recommender-Systems-Challenge-2022\HyperparameterTuning\SearchAbstractClass.py", line 326, in _evaluate_on_validation
    recommender_instance, train_time = self._fit_model(current_fit_hyperparameters)
  File "C:\Users\Luca\DataspellProjects\Recommender-Systems-Challenge-2022\HyperparameterTuning\SearchAbstractClass.py", line 297, in _fit_model
    recommender_instance.fit(*self.recommender_input_args.FIT_POSITIONAL_ARGS,
  File "C:\Users\Luca\miniconda3\lib\site-packages\sklearn\utils\_testing.py", line 320, in wrapper
    return fn(*args, **kwargs)
TypeError: fit() got an unexpected keyword argument 'validation_every_n'

SearchBayesianSkopt: Config 3 Exception. Config: {'topK': 440, 'l1_ratio': 0.0024703424146425923, 'alpha': 0.029616482656470742} - Exception: Traceback (most recent call last):
  File "C:\Users\Luca\DataspellProjects\Recommender-Systems-Challenge-2022\HyperparameterTuning\SearchAbstractClass.py", line 468, in _objective_function
    result_df, recommender_instance = self._evaluate_on_validation(current_fit_hyperparameters_dict, was_already_evaluated_flag, was_already_evaluated_index)
  File "C:\Users\Luca\DataspellProjects\Recommender-Systems-Challenge-2022\HyperparameterTuning\SearchAbstractClass.py", line 326, in _evaluate_on_validation
    recommender_instance, train_time = self._fit_model(current_fit_hyperparameters)
  File "C:\Users\Luca\DataspellProjects\Recommender-Systems-Challenge-2022\HyperparameterTuning\SearchAbstractClass.py", line 297, in _fit_model
    recommender_instance.fit(*self.recommender_input_args.FIT_POSITIONAL_ARGS,
  File "C:\Users\Luca\miniconda3\lib\site-packages\sklearn\utils\_testing.py", line 320, in wrapper
    return fn(*args, **kwargs)
TypeError: fit() got an unexpected keyword argument 'validation_every_n'

SearchBayesianSkopt: Config 4 Exception. Config: {'topK': 259, 'l1_ratio': 0.0012065302622973333, 'alpha': 0.04066465130161244} - Exception: Traceback (most recent call last):
  File "C:\Users\Luca\DataspellProjects\Recommender-Systems-Challenge-2022\HyperparameterTuning\SearchAbstractClass.py", line 468, in _objective_function
    result_df, recommender_instance = self._evaluate_on_validation(current_fit_hyperparameters_dict, was_already_evaluated_flag, was_already_evaluated_index)
  File "C:\Users\Luca\DataspellProjects\Recommender-Systems-Challenge-2022\HyperparameterTuning\SearchAbstractClass.py", line 326, in _evaluate_on_validation
    recommender_instance, train_time = self._fit_model(current_fit_hyperparameters)
  File "C:\Users\Luca\DataspellProjects\Recommender-Systems-Challenge-2022\HyperparameterTuning\SearchAbstractClass.py", line 297, in _fit_model
    recommender_instance.fit(*self.recommender_input_args.FIT_POSITIONAL_ARGS,
  File "C:\Users\Luca\miniconda3\lib\site-packages\sklearn\utils\_testing.py", line 320, in wrapper
    return fn(*args, **kwargs)
TypeError: fit() got an unexpected keyword argument 'validation_every_n'

SearchBayesianSkopt: Config 5 Exception. Config: {'topK': 338, 'l1_ratio': 0.0012392835944312363, 'alpha': 0.08272322420906213} - Exception: Traceback (most recent call last):
  File "C:\Users\Luca\DataspellProjects\Recommender-Systems-Challenge-2022\HyperparameterTuning\SearchAbstractClass.py", line 468, in _objective_function
    result_df, recommender_instance = self._evaluate_on_validation(current_fit_hyperparameters_dict, was_already_evaluated_flag, was_already_evaluated_index)
  File "C:\Users\Luca\DataspellProjects\Recommender-Systems-Challenge-2022\HyperparameterTuning\SearchAbstractClass.py", line 326, in _evaluate_on_validation
    recommender_instance, train_time = self._fit_model(current_fit_hyperparameters)
  File "C:\Users\Luca\DataspellProjects\Recommender-Systems-Challenge-2022\HyperparameterTuning\SearchAbstractClass.py", line 297, in _fit_model
    recommender_instance.fit(*self.recommender_input_args.FIT_POSITIONAL_ARGS,
  File "C:\Users\Luca\miniconda3\lib\site-packages\sklearn\utils\_testing.py", line 320, in wrapper
    return fn(*args, **kwargs)
TypeError: fit() got an unexpected keyword argument 'validation_every_n'

SearchBayesianSkopt: Config 6 Exception. Config: {'topK': 344, 'l1_ratio': 0.00314456240181515, 'alpha': 0.017416446796790056} - Exception: Traceback (most recent call last):
  File "C:\Users\Luca\DataspellProjects\Recommender-Systems-Challenge-2022\HyperparameterTuning\SearchAbstractClass.py", line 468, in _objective_function
    result_df, recommender_instance = self._evaluate_on_validation(current_fit_hyperparameters_dict, was_already_evaluated_flag, was_already_evaluated_index)
  File "C:\Users\Luca\DataspellProjects\Recommender-Systems-Challenge-2022\HyperparameterTuning\SearchAbstractClass.py", line 326, in _evaluate_on_validation
    recommender_instance, train_time = self._fit_model(current_fit_hyperparameters)
  File "C:\Users\Luca\DataspellProjects\Recommender-Systems-Challenge-2022\HyperparameterTuning\SearchAbstractClass.py", line 297, in _fit_model
    recommender_instance.fit(*self.recommender_input_args.FIT_POSITIONAL_ARGS,
  File "C:\Users\Luca\miniconda3\lib\site-packages\sklearn\utils\_testing.py", line 320, in wrapper
    return fn(*args, **kwargs)
TypeError: fit() got an unexpected keyword argument 'validation_every_n'

SearchBayesianSkopt: Config 7 Exception. Config: {'topK': 207, 'l1_ratio': 0.0022688554292989794, 'alpha': 0.0621545939196906} - Exception: Traceback (most recent call last):
  File "C:\Users\Luca\DataspellProjects\Recommender-Systems-Challenge-2022\HyperparameterTuning\SearchAbstractClass.py", line 468, in _objective_function
    result_df, recommender_instance = self._evaluate_on_validation(current_fit_hyperparameters_dict, was_already_evaluated_flag, was_already_evaluated_index)
  File "C:\Users\Luca\DataspellProjects\Recommender-Systems-Challenge-2022\HyperparameterTuning\SearchAbstractClass.py", line 326, in _evaluate_on_validation
    recommender_instance, train_time = self._fit_model(current_fit_hyperparameters)
  File "C:\Users\Luca\DataspellProjects\Recommender-Systems-Challenge-2022\HyperparameterTuning\SearchAbstractClass.py", line 297, in _fit_model
    recommender_instance.fit(*self.recommender_input_args.FIT_POSITIONAL_ARGS,
  File "C:\Users\Luca\miniconda3\lib\site-packages\sklearn\utils\_testing.py", line 320, in wrapper
    return fn(*args, **kwargs)
TypeError: fit() got an unexpected keyword argument 'validation_every_n'

SearchBayesianSkopt: Config 8 Exception. Config: {'topK': 282, 'l1_ratio': 0.00825839079739191, 'alpha': 0.05679726680104661} - Exception: Traceback (most recent call last):
  File "C:\Users\Luca\DataspellProjects\Recommender-Systems-Challenge-2022\HyperparameterTuning\SearchAbstractClass.py", line 468, in _objective_function
    result_df, recommender_instance = self._evaluate_on_validation(current_fit_hyperparameters_dict, was_already_evaluated_flag, was_already_evaluated_index)
  File "C:\Users\Luca\DataspellProjects\Recommender-Systems-Challenge-2022\HyperparameterTuning\SearchAbstractClass.py", line 326, in _evaluate_on_validation
    recommender_instance, train_time = self._fit_model(current_fit_hyperparameters)
  File "C:\Users\Luca\DataspellProjects\Recommender-Systems-Challenge-2022\HyperparameterTuning\SearchAbstractClass.py", line 297, in _fit_model
    recommender_instance.fit(*self.recommender_input_args.FIT_POSITIONAL_ARGS,
  File "C:\Users\Luca\miniconda3\lib\site-packages\sklearn\utils\_testing.py", line 320, in wrapper
    return fn(*args, **kwargs)
TypeError: fit() got an unexpected keyword argument 'validation_every_n'

SearchBayesianSkopt: Config 9 Exception. Config: {'topK': 439, 'l1_ratio': 0.0019644202863769444, 'alpha': 0.09449333882607519} - Exception: Traceback (most recent call last):
  File "C:\Users\Luca\DataspellProjects\Recommender-Systems-Challenge-2022\HyperparameterTuning\SearchAbstractClass.py", line 468, in _objective_function
    result_df, recommender_instance = self._evaluate_on_validation(current_fit_hyperparameters_dict, was_already_evaluated_flag, was_already_evaluated_index)
  File "C:\Users\Luca\DataspellProjects\Recommender-Systems-Challenge-2022\HyperparameterTuning\SearchAbstractClass.py", line 326, in _evaluate_on_validation
    recommender_instance, train_time = self._fit_model(current_fit_hyperparameters)
  File "C:\Users\Luca\DataspellProjects\Recommender-Systems-Challenge-2022\HyperparameterTuning\SearchAbstractClass.py", line 297, in _fit_model
    recommender_instance.fit(*self.recommender_input_args.FIT_POSITIONAL_ARGS,
  File "C:\Users\Luca\miniconda3\lib\site-packages\sklearn\utils\_testing.py", line 320, in wrapper
    return fn(*args, **kwargs)
TypeError: fit() got an unexpected keyword argument 'validation_every_n'

SearchBayesianSkopt: Config 10 Exception. Config: {'topK': 223, 'l1_ratio': 0.005648085089650455, 'alpha': 0.09206127157227707} - Exception: Traceback (most recent call last):
  File "C:\Users\Luca\DataspellProjects\Recommender-Systems-Challenge-2022\HyperparameterTuning\SearchAbstractClass.py", line 468, in _objective_function
    result_df, recommender_instance = self._evaluate_on_validation(current_fit_hyperparameters_dict, was_already_evaluated_flag, was_already_evaluated_index)
  File "C:\Users\Luca\DataspellProjects\Recommender-Systems-Challenge-2022\HyperparameterTuning\SearchAbstractClass.py", line 326, in _evaluate_on_validation
    recommender_instance, train_time = self._fit_model(current_fit_hyperparameters)
  File "C:\Users\Luca\DataspellProjects\Recommender-Systems-Challenge-2022\HyperparameterTuning\SearchAbstractClass.py", line 297, in _fit_model
    recommender_instance.fit(*self.recommender_input_args.FIT_POSITIONAL_ARGS,
  File "C:\Users\Luca\miniconda3\lib\site-packages\sklearn\utils\_testing.py", line 320, in wrapper
    return fn(*args, **kwargs)
TypeError: fit() got an unexpected keyword argument 'validation_every_n'

SearchBayesianSkopt: Config 11 Exception. Config: {'topK': 426, 'l1_ratio': 0.008107013868260063, 'alpha': 0.023050486391736822} - Exception: Traceback (most recent call last):
  File "C:\Users\Luca\DataspellProjects\Recommender-Systems-Challenge-2022\HyperparameterTuning\SearchAbstractClass.py", line 468, in _objective_function
    result_df, recommender_instance = self._evaluate_on_validation(current_fit_hyperparameters_dict, was_already_evaluated_flag, was_already_evaluated_index)
  File "C:\Users\Luca\DataspellProjects\Recommender-Systems-Challenge-2022\HyperparameterTuning\SearchAbstractClass.py", line 326, in _evaluate_on_validation
    recommender_instance, train_time = self._fit_model(current_fit_hyperparameters)
  File "C:\Users\Luca\DataspellProjects\Recommender-Systems-Challenge-2022\HyperparameterTuning\SearchAbstractClass.py", line 297, in _fit_model
    recommender_instance.fit(*self.recommender_input_args.FIT_POSITIONAL_ARGS,
  File "C:\Users\Luca\miniconda3\lib\site-packages\sklearn\utils\_testing.py", line 320, in wrapper
    return fn(*args, **kwargs)
TypeError: fit() got an unexpected keyword argument 'validation_every_n'

SearchBayesianSkopt: Config 12 Exception. Config: {'topK': 396, 'l1_ratio': 0.0062745229848876986, 'alpha': 0.014215924285073908} - Exception: Traceback (most recent call last):
  File "C:\Users\Luca\DataspellProjects\Recommender-Systems-Challenge-2022\HyperparameterTuning\SearchAbstractClass.py", line 468, in _objective_function
    result_df, recommender_instance = self._evaluate_on_validation(current_fit_hyperparameters_dict, was_already_evaluated_flag, was_already_evaluated_index)
  File "C:\Users\Luca\DataspellProjects\Recommender-Systems-Challenge-2022\HyperparameterTuning\SearchAbstractClass.py", line 326, in _evaluate_on_validation
    recommender_instance, train_time = self._fit_model(current_fit_hyperparameters)
  File "C:\Users\Luca\DataspellProjects\Recommender-Systems-Challenge-2022\HyperparameterTuning\SearchAbstractClass.py", line 297, in _fit_model
    recommender_instance.fit(*self.recommender_input_args.FIT_POSITIONAL_ARGS,
  File "C:\Users\Luca\miniconda3\lib\site-packages\sklearn\utils\_testing.py", line 320, in wrapper
    return fn(*args, **kwargs)
TypeError: fit() got an unexpected keyword argument 'validation_every_n'

SearchBayesianSkopt: Config 13 Exception. Config: {'topK': 244, 'l1_ratio': 0.0013790686263045967, 'alpha': 0.05483729644390722} - Exception: Traceback (most recent call last):
  File "C:\Users\Luca\DataspellProjects\Recommender-Systems-Challenge-2022\HyperparameterTuning\SearchAbstractClass.py", line 468, in _objective_function
    result_df, recommender_instance = self._evaluate_on_validation(current_fit_hyperparameters_dict, was_already_evaluated_flag, was_already_evaluated_index)
  File "C:\Users\Luca\DataspellProjects\Recommender-Systems-Challenge-2022\HyperparameterTuning\SearchAbstractClass.py", line 326, in _evaluate_on_validation
    recommender_instance, train_time = self._fit_model(current_fit_hyperparameters)
  File "C:\Users\Luca\DataspellProjects\Recommender-Systems-Challenge-2022\HyperparameterTuning\SearchAbstractClass.py", line 297, in _fit_model
    recommender_instance.fit(*self.recommender_input_args.FIT_POSITIONAL_ARGS,
  File "C:\Users\Luca\miniconda3\lib\site-packages\sklearn\utils\_testing.py", line 320, in wrapper
    return fn(*args, **kwargs)
TypeError: fit() got an unexpected keyword argument 'validation_every_n'

SearchBayesianSkopt: Config 14 Exception. Config: {'topK': 345, 'l1_ratio': 0.0028130670234593302, 'alpha': 0.06437406778106432} - Exception: Traceback (most recent call last):
  File "C:\Users\Luca\DataspellProjects\Recommender-Systems-Challenge-2022\HyperparameterTuning\SearchAbstractClass.py", line 468, in _objective_function
    result_df, recommender_instance = self._evaluate_on_validation(current_fit_hyperparameters_dict, was_already_evaluated_flag, was_already_evaluated_index)
  File "C:\Users\Luca\DataspellProjects\Recommender-Systems-Challenge-2022\HyperparameterTuning\SearchAbstractClass.py", line 326, in _evaluate_on_validation
    recommender_instance, train_time = self._fit_model(current_fit_hyperparameters)
  File "C:\Users\Luca\DataspellProjects\Recommender-Systems-Challenge-2022\HyperparameterTuning\SearchAbstractClass.py", line 297, in _fit_model
    recommender_instance.fit(*self.recommender_input_args.FIT_POSITIONAL_ARGS,
  File "C:\Users\Luca\miniconda3\lib\site-packages\sklearn\utils\_testing.py", line 320, in wrapper
    return fn(*args, **kwargs)
TypeError: fit() got an unexpected keyword argument 'validation_every_n'

SearchBayesianSkopt: Search interrupted. No valid config was found during the initial random initialization
